<?xml version="1.0" encoding="utf-8"?>
<!-- =================================================================================== -->
<!-- |    This document was autogenerated by xacro from elegriparm.xacro               | -->
<!-- |    EDITING THIS FILE BY HAND IS NOT RECOMMENDED                                 | -->
<!-- =================================================================================== -->
<robot name="elegriparm">
  <material name="silver">
    <color rgba="0.700 0.700 0.700 1.000"/>
  </material>
  <transmission name="Rev46_tran">
    <type>transmission_interface/SimpleTransmission</type>
    <joint name="Rev46">
      <hardwareInterface>hardware_interface/EffortJointInterface</hardwareInterface>
    </joint>
    <actuator name="Rev46_actr">
      <hardwareInterface>hardware_interface/EffortJointInterface</hardwareInterface>
      <mechanicalReduction>1</mechanicalReduction>
    </actuator>
  </transmission>
  <transmission name="Rev47_tran">
    <type>transmission_interface/SimpleTransmission</type>
    <joint name="Rev47">
      <hardwareInterface>hardware_interface/EffortJointInterface</hardwareInterface>
    </joint>
    <actuator name="Rev47_actr">
      <hardwareInterface>hardware_interface/EffortJointInterface</hardwareInterface>
      <mechanicalReduction>1</mechanicalReduction>
    </actuator>
  </transmission>
  <transmission name="Rev48_tran">
    <type>transmission_interface/SimpleTransmission</type>
    <joint name="Rev48">
      <hardwareInterface>hardware_interface/EffortJointInterface</hardwareInterface>
    </joint>
    <actuator name="Rev48_actr">
      <hardwareInterface>hardware_interface/EffortJointInterface</hardwareInterface>
      <mechanicalReduction>1</mechanicalReduction>
    </actuator>
  </transmission>
  <transmission name="Rev50_tran">
    <type>transmission_interface/SimpleTransmission</type>
    <joint name="Rev50">
      <hardwareInterface>hardware_interface/EffortJointInterface</hardwareInterface>
    </joint>
    <actuator name="Rev50_actr">
      <hardwareInterface>hardware_interface/EffortJointInterface</hardwareInterface>
      <mechanicalReduction>1</mechanicalReduction>
    </actuator>
  </transmission>
  <transmission name="Rev51_tran">
    <type>transmission_interface/SimpleTransmission</type>
    <joint name="Rev51">
      <hardwareInterface>hardware_interface/EffortJointInterface</hardwareInterface>
    </joint>
    <actuator name="Rev51_actr">
      <hardwareInterface>hardware_interface/EffortJointInterface</hardwareInterface>
      <mechanicalReduction>1</mechanicalReduction>
    </actuator>
  </transmission>
  <transmission name="Rev52_tran">
    <type>transmission_interface/SimpleTransmission</type>
    <joint name="Rev52">
      <hardwareInterface>hardware_interface/EffortJointInterface</hardwareInterface>
    </joint>
    <actuator name="Rev52_actr">
      <hardwareInterface>hardware_interface/EffortJointInterface</hardwareInterface>
      <mechanicalReduction>1</mechanicalReduction>
    </actuator>
  </transmission>
  <transmission name="Rev53_tran">
    <type>transmission_interface/SimpleTransmission</type>
    <joint name="Rev53">
      <hardwareInterface>hardware_interface/EffortJointInterface</hardwareInterface>
    </joint>
    <actuator name="Rev53_actr">
      <hardwareInterface>hardware_interface/EffortJointInterface</hardwareInterface>
      <mechanicalReduction>1</mechanicalReduction>
    </actuator>
  </transmission>
  <transmission name="Rev60_tran">
    <type>transmission_interface/SimpleTransmission</type>
    <joint name="Rev60">
      <hardwareInterface>hardware_interface/EffortJointInterface</hardwareInterface>
    </joint>
    <actuator name="Rev60_actr">
      <hardwareInterface>hardware_interface/EffortJointInterface</hardwareInterface>
      <mechanicalReduction>1</mechanicalReduction>
    </actuator>
  </transmission>
  <gazebo>
    <plugin filename="libgazebo_ros_control.so" name="control"/>
  </gazebo>
  <gazebo reference="base_link">
    <material>Gazebo/Silver</material>
    <mu1>0.2</mu1>
    <mu2>0.2</mu2>
    <selfCollide>true</selfCollide>
    <gravity>true</gravity>
  </gazebo>
  <gazebo reference="link1_1">
    <material>Gazebo/Silver</material>
    <mu1>0.2</mu1>
    <mu2>0.2</mu2>
    <selfCollide>true</selfCollide>
  </gazebo>
  <gazebo reference="link2_1">
    <material>Gazebo/Silver</material>
    <mu1>0.2</mu1>
    <mu2>0.2</mu2>
    <selfCollide>true</selfCollide>
  </gazebo>
  <gazebo reference="link3_1">
    <material>Gazebo/Silver</material>
    <mu1>0.2</mu1>
    <mu2>0.2</mu2>
    <selfCollide>true</selfCollide>
  </gazebo>
  <gazebo reference="link5_1">
    <material>Gazebo/Silver</material>
    <mu1>0.2</mu1>
    <mu2>0.2</mu2>
    <selfCollide>true</selfCollide>
  </gazebo>
  <gazebo reference="link6_1">
    <material>Gazebo/Silver</material>
    <mu1>0.2</mu1>
    <mu2>0.2</mu2>
    <selfCollide>true</selfCollide>
  </gazebo>
  <gazebo reference="link7_1">
    <material>Gazebo/Silver</material>
    <mu1>0.2</mu1>
    <mu2>0.2</mu2>
    <selfCollide>true</selfCollide>
  </gazebo>
  <gazebo reference="link8_1">
    <material>Gazebo/Silver</material>
    <mu1>0.2</mu1>
    <mu2>0.2</mu2>
    <selfCollide>true</selfCollide>
  </gazebo>
  <gazebo reference="link4_1">
    <material>Gazebo/Silver</material>
    <mu1>0.2</mu1>
    <mu2>0.2</mu2>
    <selfCollide>true</selfCollide>
  </gazebo>
  <link name="base_link">
    <inertial>
      <origin rpy="0 0 0" xyz="-2.6378267996385318e-05 -2.982904930888828e-05 0.0452416392508935"/>
      <mass value="855.6902182513435"/>
      <inertia ixx="88.194887" ixy="-0.004914" ixz="0.003004" iyy="88.185464" iyz="0.003488" izz="173.450328"/>
    </inertial>
    <visual>
      <origin rpy="0 0 0" xyz="0 0 0"/>
      <geometry>
        <mesh filename="package://elegriparm_description/meshes/base_link.stl" scale="0.001 0.001 0.001"/>
      </geometry>
      <material name="silver"/>
    </visual>
    <collision>
      <origin rpy="0 0 0" xyz="0 0 0"/>
      <geometry>
        <mesh filename="package://elegriparm_description/meshes/base_link.stl" scale="0.001 0.001 0.001"/>
      </geometry>
    </collision>
  </link>
  <link name="link1_1">
    <inertial>
      <origin rpy="0 0 0" xyz="0.012552259756380054 -0.014820493391146296 0.20074728180211923"/>
      <mass value="162.8353483389851"/>
      <inertia ixx="2.522973" ixy="0.26063" ixz="-0.067697" iyy="2.435738" iyz="0.07993" izz="1.773971"/>
    </inertial>
    <visual>
      <origin rpy="0 0 0" xyz="-0.0 0.0 -0.155"/>
      <geometry>
        <mesh filename="package://elegriparm_description/meshes/link1_1.stl" scale="0.001 0.001 0.001"/>
      </geometry>
      <material name="silver"/>
    </visual>
    <collision>
      <origin rpy="0 0 0" xyz="-0.0 0.0 -0.155"/>
      <geometry>
        <mesh filename="package://elegriparm_description/meshes/link1_1.stl" scale="0.001 0.001 0.001"/>
      </geometry>
    </collision>
  </link>
  <link name="link2_1">
    <inertial>
      <origin rpy="0 0 0" xyz="0.37718159984781086 -0.16304278711013198 -0.027869527473308564"/>
      <mass value="16.3345971734594"/>
      <inertia ixx="0.080874" ixy="0.004955" ixz="0.007658" iyy="0.080039" iyz="-0.008312" izz="0.075837"/>
    </inertial>
    <visual>
      <origin rpy="0 0 0" xyz="0.157727 0.099531 -0.430868"/>
      <geometry>
        <mesh filename="package://elegriparm_description/meshes/link2_1.stl" scale="0.001 0.001 0.001"/>
      </geometry>
      <material name="silver"/>
    </visual>
    <collision>
      <origin rpy="0 0 0" xyz="0.157727 0.099531 -0.430868"/>
      <geometry>
        <mesh filename="package://elegriparm_description/meshes/link2_1.stl" scale="0.001 0.001 0.001"/>
      </geometry>
    </collision>
  </link>
  <link name="link3_1">
    <inertial>
      <origin rpy="0 0 0" xyz="4.174088950870125e-07 -3.563244375670571e-07 0.3150003051274889"/>
      <mass value="58.287075422588"/>
      <inertia ixx="1.982512" ixy="0.0" ixz="-0.0" iyy="1.982512" iyz="-0.0" izz="0.109334"/>
    </inertial>
    <visual>
      <origin rpy="0 0 0" xyz="-0.18738 0.225644 -0.4817"/>
      <geometry>
        <mesh filename="package://elegriparm_description/meshes/link3_1.stl" scale="0.001 0.001 0.001"/>
      </geometry>
      <material name="silver"/>
    </visual>
    <collision>
      <origin rpy="0 0 0" xyz="-0.18738 0.225644 -0.4817"/>
      <geometry>
        <mesh filename="package://elegriparm_description/meshes/link3_1.stl" scale="0.001 0.001 0.001"/>
      </geometry>
    </collision>
  </link>
  <link name="link5_1">
    <inertial>
      <origin rpy="0 0 0" xyz="0.006460681422399042 -0.01241626832551379 0.002097716132566596"/>
      <mass value="16.33458651273331"/>
      <inertia ixx="0.06605" ixy="0.005491" ixz="-0.002227" iyy="0.08552" iyz="0.000529" izz="0.08518"/>
    </inertial>
    <visual>
      <origin rpy="0 0 0" xyz="0.043671 0.358677 -1.204533"/>
      <geometry>
        <mesh filename="package://elegriparm_description/meshes/link5_1.stl" scale="0.001 0.001 0.001"/>
      </geometry>
      <material name="silver"/>
    </visual>
    <collision>
      <origin rpy="0 0 0" xyz="0.043671 0.358677 -1.204533"/>
      <geometry>
        <mesh filename="package://elegriparm_description/meshes/link5_1.stl" scale="0.001 0.001 0.001"/>
      </geometry>
    </collision>
  </link>
  <link name="link6_1">
    <inertial>
      <origin rpy="0 0 0" xyz="0.12025593535505269 -0.21189518084320091 0.025763419455570924"/>
      <mass value="47.776682043389435"/>
      <inertia ixx="0.784226" ixy="0.385763" ixz="-0.046904" iyy="0.323425" iyz="0.082647" izz="0.993106"/>
    </inertial>
    <visual>
      <origin rpy="0 0 0" xyz="-0.043896 0.414929 -1.215943"/>
      <geometry>
        <mesh filename="package://elegriparm_description/meshes/link6_1.stl" scale="0.001 0.001 0.001"/>
      </geometry>
      <material name="silver"/>
    </visual>
    <collision>
      <origin rpy="0 0 0" xyz="-0.043896 0.414929 -1.215943"/>
      <geometry>
        <mesh filename="package://elegriparm_description/meshes/link6_1.stl" scale="0.001 0.001 0.001"/>
      </geometry>
    </collision>
  </link>
  <link name="link7_1">
    <inertial>
      <origin rpy="0 0 0" xyz="0.10237209013635501 -0.043341227116188596 0.01330882364025121"/>
      <mass value="62.39336668118014"/>
      <inertia ixx="0.352989" ixy="-0.255612" ixz="-0.022779" iyy="0.688749" iyz="-0.010194" izz="0.836734"/>
    </inertial>
    <visual>
      <origin rpy="0 0 0" xyz="-0.284408 0.83872 -1.26747"/>
      <geometry>
        <mesh filename="package://elegriparm_description/meshes/link7_1.stl" scale="0.001 0.001 0.001"/>
      </geometry>
      <material name="silver"/>
    </visual>
    <collision>
      <origin rpy="0 0 0" xyz="-0.284408 0.83872 -1.26747"/>
      <geometry>
        <mesh filename="package://elegriparm_description/meshes/link7_1.stl" scale="0.001 0.001 0.001"/>
      </geometry>
    </collision>
  </link>
  <link name="link8_1">
    <inertial>
      <origin rpy="0 0 0" xyz="-0.020310230742140334 -0.009607967604363443 0.06712602452313687"/>
      <mass value="28.09297060145581"/>
      <inertia ixx="0.213748" ixy="-0.012252" ixz="0.051433" iyy="0.231658" iyz="0.025643" izz="0.124731"/>
    </inertial>
    <visual>
      <origin rpy="0 0 0" xyz="-0.561048 0.786497 -1.288517"/>
      <geometry>
        <mesh filename="package://elegriparm_description/meshes/link8_1.stl" scale="0.001 0.001 0.001"/>
      </geometry>
      <material name="silver"/>
    </visual>
    <collision>
      <origin rpy="0 0 0" xyz="-0.561048 0.786497 -1.288517"/>
      <geometry>
        <mesh filename="package://elegriparm_description/meshes/link8_1.stl" scale="0.001 0.001 0.001"/>
      </geometry>
    </collision>
  </link>
  <link name="link4_1">
    <inertial>
      <origin rpy="0 0 0" xyz="-0.05744272173050652 -0.03431687311802767 0.08905783463041961"/>
      <mass value="61.145733834937005"/>
      <inertia ixx="0.357472" ixy="-0.264206" ixz="0.013096" iyy="0.671505" iyz="0.008209" izz="0.809876"/>
    </inertial>
    <visual>
      <origin rpy="0 0 0" xyz="-0.18738 0.225644 -1.1117"/>
      <geometry>
        <mesh filename="package://elegriparm_description/meshes/link4_1.stl" scale="0.001 0.001 0.001"/>
      </geometry>
      <material name="silver"/>
    </visual>
    <collision>
      <origin rpy="0 0 0" xyz="-0.18738 0.225644 -1.1117"/>
      <geometry>
        <mesh filename="package://elegriparm_description/meshes/link4_1.stl" scale="0.001 0.001 0.001"/>
      </geometry>
    </collision>
  </link>
  <joint name="Rev46" type="continuous">
    <origin rpy="0 0 0" xyz="0.0 0.0 0.155"/>
    <parent link="base_link"/>
    <child link="link1_1"/>
    <axis xyz="0.0 0.0 1.0"/>
  </joint>
  <joint name="Rev47" type="revolute">
    <origin rpy="0 0 0" xyz="-0.157727 -0.099531 0.275868"/>
    <parent link="link1_1"/>
    <child link="link2_1"/>
    <axis xyz="0.639504 -0.768788 -0.0"/>
    <limit effort="100" lower="-0.872665" upper="0.698132" velocity="100"/>
  </joint>
  <joint name="Rev48" type="revolute">
    <origin rpy="0 0 0" xyz="0.345107 -0.126113 0.050832"/>
    <parent link="link2_1"/>
    <child link="link3_1"/>
    <axis xyz="0.0 0.0 1.0"/>
    <limit effort="100" lower="-1.570796" upper="1.570796" velocity="100"/>
  </joint>
  <joint name="Rev50" type="revolute">
    <origin rpy="0 0 0" xyz="-0.231051 -0.133033 0.092833"/>
    <parent link="link4_1"/>
    <child link="link5_1"/>
    <axis xyz="-0.869702 -0.493576 -0.0"/>
    <limit effort="100" lower="-1.570796" upper="1.570796" velocity="100"/>
  </joint>
  <joint name="Rev51" type="revolute">
    <origin rpy="0 0 0" xyz="0.087567 -0.056252 0.01141"/>
    <parent link="link5_1"/>
    <child link="link6_1"/>
    <axis xyz="0.49084 -0.86488 0.105158"/>
    <limit effort="100" lower="-0.872665" upper="3.141593" velocity="100"/>
  </joint>
  <joint name="Rev52" type="revolute">
    <origin rpy="0 0 0" xyz="0.240512 -0.423791 0.051527"/>
    <parent link="link6_1"/>
    <child link="link7_1"/>
    <axis xyz="0.49084 -0.86488 0.105158"/>
    <limit effort="100" lower="-1.570796" upper="2.268928" velocity="100"/>
  </joint>
  <joint name="Rev53" type="revolute">
    <origin rpy="0 0 0" xyz="0.27664 0.052223 0.021047"/>
    <parent link="link7_1"/>
    <child link="link8_1"/>
    <axis xyz="0.867241 0.496575 0.036152"/>
    <limit effort="100" lower="-1.745329" upper="-0.174533" velocity="100"/>
  </joint>
  <joint name="Rev60" type="revolute">
    <origin rpy="0 0 0" xyz="0.0 0.0 0.63"/>
    <parent link="link3_1"/>
    <child link="link4_1"/>
    <axis xyz="0.0 0.0 1.0"/>
    <limit effort="100" lower="-1.570796" upper="1.570796" velocity="100"/>
  </joint>
</robot>

